<?xml version="1.0" encoding="utf-8"?>
<!-- This URDF was automatically created by SolidWorks to URDF Exporter! Originally created by Stephen Brawner (brawner@gmail.com) 
     Commit Version: 1.6.0-4-g7f85cfe  Build Version: 1.6.7995.38578
     For more information, please see http://wiki.ros.org/sw_urdf_exporter -->
<robot
  name="Dual_arm_URDF_exported2.SLDASM">

  <!--  This is world setting  -->
  <!--  The robot's base should be rigidly attached to the world's link-->
  <link name="world"/>  
  <joint  name="base_joint"
    type="fixed">
    <parent link="world"/>
    <child link="Link_base"/>
    <origin rpy="0 0 0" xyz="0.0 0.0 0.17"/>
  </joint>
  
  <!--  This is  Link setting  -->
  <link name="Link_base">
    <inertial>
      <origin
        xyz="5.70342951597749E-17 -2.07083673802511E-18 0.16596933226608"
        rpy="0 0 0" />
      <mass
        value="175.473579205783" />
      <inertia
        ixx="187.97215343815"
        ixy="-1.17446412092729E-15"
        ixz="-1.67737550768459E-15"
        iyy="8.44456814716498"
        iyz="1.16719929426561E-15"
        izz="186.006758946794" />
    </inertial>
    <visual>
      <origin
        xyz="0 0 0"
        rpy="0 0 0" />
      <geometry>
        <mesh
          filename="package://Dual_arm_URDF_exported2.SLDASM/meshes/Link_base.STL" />
      </geometry>
      <material
        name="">
        <color
          rgba="0.792156862745098 0.819607843137255 0.933333333333333 1" />
      </material>
    </visual>
    <collision>
      <origin
        xyz="0 0 0"
        rpy="0 0 0" />
      <geometry>
        <mesh          filename="package://Dual_arm_URDF_exported2.SLDASM/meshes/Link_base.STL" />
      </geometry>
    </collision>
  </link>
      <!--  Object -->
  <link name="Link_object">
    <inertial>
      <origin
        xyz="0 2.7756E-17 0"
        rpy="0 0 0" />
      <mass
        value="32" />
      <inertia
        ixx="0.21333"
        ixy="0"
        ixz="0"
        iyy="1.8133"
        iyz="0"
        izz="1.8133" />
    </inertial>
    <visual>
      <origin
        xyz="0 0 0"
        rpy="0 0 0" />
      <geometry>
        <mesh
          filename="package://Dual_arm_URDF_exported2.SLDASM/meshes/Link_object.STL" />
      </geometry>
      <material
        name="">
        <color
          rgba="0.79216 0.81961 0.93333 1" />
      </material>
    </visual>
    <collision>
      <origin
        xyz="0 0 0"
        rpy="0 0 0" />
      <geometry>
        <mesh          filename="package://Dual_arm_URDF_exported2.SLDASM/meshes/Link_object.STL" />
      </geometry>
    </collision>
  </link>
      <!--  Left arm Links -->
  <link name="Link_0_left">
    <inertial>
      <origin
        xyz="0.0257253404742335 0.267068280633129 -0.000422587192071511"
        rpy="0 0 0" />
      <mass
        value="44.0003903821512" />
      <inertia
        ixx="0.510206684006508"
        ixy="-0.108718830381331"
        ixz="0.00174239844646739"
        iyy="0.693171643365736"
        iyz="0.00089849322093645"
        izz="0.72220726061105" />
    </inertial>
    <visual>
      <origin
        xyz="0 0 0"
        rpy="0 0 0" />
      <geometry>
        <mesh
          filename="package://Dual_arm_URDF_exported2.SLDASM/meshes/Link_0_left.STL" />
      </geometry>
      <material
        name="">
        <color
          rgba="0.752941176470588 0.752941176470588 0.752941176470588 1" />
      </material>
    </visual>
    <collision>
      <origin
        xyz="0 0 0"
        rpy="0 0 0" />
      <geometry>
        <mesh          filename="package://Dual_arm_URDF_exported2.SLDASM/meshes/Link_0_left.STL" />
      </geometry>
    </collision>
  </link>

  <link name="Link_1_left">
    <inertial>
      <origin
        xyz="0.220100104353883 -0.000353201939205627 -0.0818491698881182"
        rpy="0 0 0" />
      <mass
        value="11.1204795622201" />
      <inertia
        ixx="0.0394927321862162"
        ixy="-0.000101248256734392"
        ixz="-0.0449284723464891"
        iyy="0.528728735688798"
        iyz="0.000116486713577521"
        izz="0.539153697001847" />
    </inertial>
    <visual>
      <origin
        xyz="0 0 0"
        rpy="0 0 0" />
      <geometry>
        <mesh
          filename="package://Dual_arm_URDF_exported2.SLDASM/meshes/Link_1_left.STL" />
      </geometry>
      <material
        name="">
        <color
          rgba="0.752941176470588 0.752941176470588 0.752941176470588 1" />
      </material>
    </visual>
    <collision>
      <origin
        xyz="0 0 0"
        rpy="0 0 0" />
      <geometry>
        <mesh          filename="package://Dual_arm_URDF_exported2.SLDASM/meshes/Link_1_left.STL" />
      </geometry>
    </collision>
  </link>

  <link name="Link_2_left">
    <inertial>
      <origin
        xyz="0.19683 0.033549 0.088122"
        rpy="0 0 0" />
      <mass
        value="12.054" />
      <inertia
        ixx="0.049645"
        ixy="-0.010896"
        ixz="0.0012034"
        iyy="0.1236"
        iyz="0.00064683"
        izz="0.13094" />
    </inertial>
    <visual>
      <origin
        xyz="0 0 0"
        rpy="0 0 0" />
      <geometry>
        <mesh
          filename="package://Dual_arm_URDF_exported2.SLDASM/meshes/Link_2_left.STL" />
      </geometry>
      <material
        name="">
        <color
          rgba="0.75294 0.75294 0.75294 1" />
      </material>
    </visual>
    <collision>
      <origin
        xyz="0 0 0"
        rpy="0 0 0" />
      <geometry>
        <mesh          filename="package://Dual_arm_URDF_exported2.SLDASM/meshes/Link_2_left.STL" />
      </geometry>
    </collision>
  </link>

  <link name="Link_3_left">
    <inertial>
      <origin
        xyz="0.017057385622842 -9.55062087193426E-08 0.0420061621566496"
        rpy="0 0 0" />
      <mass
        value="0.828810415472124" />
      <inertia
        ixx="0.000897507811096277"
        ixy="-1.36925090097017E-09"
        ixz="-3.31460866812027E-08"
        iyy="0.00135949204117929"
        iyz="-5.18258478194708E-11"
        izz="0.00136817872211275" />
    </inertial>
    <visual>
      <origin
        xyz="0 0 0"
        rpy="0 0 0" />
      <geometry>
        <mesh
          filename="package://Dual_arm_URDF_exported2.SLDASM/meshes/Link_3_left.STL" />
      </geometry>
      <material
        name="">
        <color
          rgba="0.752941176470588 0.752941176470588 0.752941176470588 1" />
      </material>
    </visual>
    <collision>
      <origin
        xyz="0 0 0"
        rpy="0 0 0" />
      <geometry>
        <mesh          filename="package://Dual_arm_URDF_exported2.SLDASM/meshes/Link_3_left.STL" />
      </geometry>
    </collision>
  </link>
      <!--  Right arm Links -->
  <link name="Link_0_right">
    <inertial>
      <origin
        xyz="0 0 0"
        rpy="0 0 0" />
      <mass
        value="0" />
      <inertia
        ixx="0"
        ixy="0"
        ixz="0"
        iyy="0"
        iyz="0"
        izz="0" />
    </inertial>
    <visual>
      <origin
        xyz="0 0 0"
        rpy="0 0 0" />
      <geometry>
        <mesh
          filename="package://Dual_arm_URDF_exported2.SLDASM/meshes/Link_0_right.STL" />
      </geometry>
      <material
        name="">
        <color
          rgba="1 1 1 1" />
      </material>
    </visual>
    <collision>
      <origin
        xyz="0 0 0"
        rpy="0 0 0" />
      <geometry>
        <mesh          filename="package://Dual_arm_URDF_exported2.SLDASM/meshes/Link_0_right.STL" />
      </geometry>
    </collision>
  </link>

  <link name="Link_1_right">
    <inertial>
      <origin
        xyz="0.2201 -0.0003532 -0.081849"
        rpy="0 0 0" />
      <mass
        value="11.12" />
      <inertia
        ixx="0.039493"
        ixy="-0.00010125"
        ixz="-0.044928"
        iyy="0.52873"
        iyz="0.00011649"
        izz="0.53915" />
    </inertial>
    <visual>
      <origin
        xyz="0 0 0"
        rpy="0 0 0" />
      <geometry>
        <mesh
          filename="package://Dual_arm_URDF_exported2.SLDASM/meshes/Link_1_right.STL" />
      </geometry>
      <material
        name="">
        <color
          rgba="0.75294 0.75294 0.75294 1" />
      </material>
    </visual>
    <collision>
      <origin
        xyz="0 0 0"
        rpy="0 0 0" />
      <geometry>
        <mesh          filename="package://Dual_arm_URDF_exported2.SLDASM/meshes/Link_1_right.STL" />
      </geometry>
    </collision>
  </link>

  <link name="Link_2_right">
    <inertial>
      <origin
        xyz="0.19683 0.033549 0.088122"
        rpy="0 0 0" />
      <mass
        value="12.054" />
      <inertia
        ixx="0.049645"
        ixy="-0.010896"
        ixz="0.0012034"
        iyy="0.1236"
        iyz="0.00064683"
        izz="0.13094" />
    </inertial>
    <visual>
      <origin
        xyz="0 0 0"
        rpy="0 0 0" />
      <geometry>
        <mesh
          filename="package://Dual_arm_URDF_exported2.SLDASM/meshes/Link_2_right.STL" />
      </geometry>
      <material
        name="">
        <color
          rgba="0.75294 0.75294 0.75294 1" />
      </material>
    </visual>
    <collision>
      <origin
        xyz="0 0 0"
        rpy="0 0 0" />
      <geometry>
        <mesh filename="package://Dual_arm_URDF_exported2.SLDASM/meshes/Link_2_right.STL" />
      </geometry>
    </collision>
  </link>

  <link name="Link_3_right">
    <inertial>
      <origin
        xyz="0.0170573856228414 -9.55062089413872E-08 0.0420061621566493"
        rpy="0 0 0" />
      <mass
        value="0.828810415472125" />
      <inertia
        ixx="0.000897507811096279"
        ixy="-1.36925089502359E-09"
        ixz="-3.31460866811767E-08"
        iyy="0.00135949204117929"
        iyz="-5.18258481495072E-11"
        izz="0.00136817872211275" />
    </inertial>
    <visual>
      <origin
        xyz="0 0 0"
        rpy="0 0 0" />
      <geometry>
        <mesh          filename="package://Dual_arm_URDF_exported2.SLDASM/meshes/Link_3_right.STL" />
      </geometry>
      <material
        name="">
        <color          rgba="0.752941176470588 0.752941176470588 0.752941176470588 1" />
      </material>
    </visual>
    <collision>
      <origin
        xyz="0 0 0"
        rpy="0 0 0" />
      <geometry>
        <mesh filename="package://Dual_arm_URDF_exported2.SLDASM/meshes/Link_3_right.STL" />
      </geometry>
    </collision>
  </link>

  <!--  This is Joints setting  -->
      <!--  Object Joint -->
  <joint  name="Joint_0_object"
    type="fixed">
    <origin
      xyz="0 -0.01178 0.15"
      rpy="1.5708 0 1.5708" />
    <parent link="Link_base" />
    <child  link="Link_object" />
    <axis   xyz="0 0 0" />
  </joint>
      <!--  Left arm Joints -->
  <joint  name="Joint_0_left"
    type="fixed">
    <origin
      xyz="0 -1.18 0.55"
      rpy="1.5708 0 1.5708" />
    <parent link="Link_base" />
    <child  link="Link_0_left" />
    <axis   xyz="0 0 0" />
  </joint>

  <joint  name="Joint_1_left"
    type="continuous">
    <origin
      xyz="0.18 0.475 -0.0875"
      rpy="0 0 0" />
    <parent link="Link_0_left" />
    <child  link="Link_1_left" />
    <axis   xyz="0 0 1" />
  </joint>

  <joint  name="Joint_2_left"
    type="continuous">
    <origin
      xyz="0.52 0 0"
      rpy="0 0 0" />
    <parent link="Link_1_left" />
    <child  link="Link_2_left" />
    <axis   xyz="0 0 1" />
  </joint>

  <joint  name="Joint_3_left"
    type="continuous">
    <origin
      xyz="0.59841 0 0.0455"
      rpy="0 0 0" />
    <parent link="Link_2_left" />
    <child  link="Link_3_left" />
    <axis   xyz="0 0 1" />
  </joint>
      <!--  Right arm Joints -->
  <joint  name="Joint_0_right"
    type="fixed">
    <origin
      xyz="0 1.18 0.55"
      rpy="1.5708 0 -1.5708" />
    <parent link="Link_base" />
    <child  link="Link_0_right" />
    <axis   xyz="0 0 0" />
  </joint>

  <joint  name="Joint_1_right"
    type="continuous">
    <origin
      xyz="0.18 0.475 -0.0875"
      rpy="0 0 0" />
    <parent link="Link_0_right" />
    <child  link="Link_1_right" />
    <axis   xyz="0 0 -1" />
  </joint>

  <joint  name="Joint_2_right"
    type="continuous">
    <origin
      xyz="0.52 0 0"
      rpy="0 0 0" />
    <parent link="Link_1_right" />
    <child  link="Link_2_right" />
    <axis   xyz="0 0 -1" />
  </joint>

  <joint  name="Joint_3_right"
    type="continuous">
    <origin
      xyz="0.59841 0 0.0455"
      rpy="0 0 0" />
    <parent link="Link_2_right" />
    <child  link="Link_3_right" />
    <axis   xyz="0 0 -1" />
  </joint>
</robot>